<mujoco model="Assy_car_ver1">
    <compiler angle="radian" meshdir="meshes/" />
    <size njmax="500" nconmax="100" />
    <asset>
        <mesh name="reference_plate" file="reference_plate.STL" />
        <mesh name="main_body_car" file="main_body.STL" />
        <mesh name="front_axis" file="front_axis.STL" />
        <mesh name="FL_wheel" file="FL_wheel.STL" />
        <mesh name="FR_wheel" file="FR_wheel.STL" />
        <mesh name="BL_wheel" file="BL_wheel.STL" />
        <mesh name="BR_wheel" file="BR_wheel.STL" />
    </asset>
    <worldbody>
        <geom type="mesh" contype="0" conaffinity="0" group="1" rgba="0.792157 0.819608 0.933333 1" mesh="reference_plate" />
        <geom type="mesh" rgba="0.792157 0.819608 0.933333 1" mesh="reference_plate" />
        <body name="main_body" pos="0 0 0" quat="0 0 0.707107 0.707107">
            <inertial pos="-0.0716966 0.0590631 0" quat="0.525785 0.525785 0.472811 0.472811" mass="16.0322" diaginertia="0.696332 0.491238 0.245138" />
            <joint name="ref_to_mainbody" pos="0 0 0" axis="0 1 0" />
            <geom type="mesh" contype="0" conaffinity="0" group="1" rgba="0.792157 0.819608 0.933333 1" mesh="main_body" />
            <geom type="mesh" rgba="0.792157 0.819608 0.933333 1" mesh="main_body" />
            <body name="front_axis" pos="-0.22 0 0" quat="0 0.707107 0 -0.707107">
                <inertial pos="5.93917e-11 0.0457281 -6.0697e-09" quat="0 0.707107 0 0.707107" mass="0.0276778" diaginertia="0.000258681 0.000254859 4.21682e-06" />
                <joint name="main_to_axis" pos="0 0 0" axis="0 1 0" />
                <geom type="mesh" contype="0" conaffinity="0" group="1" rgba="0.792157 0.819608 0.933333 1" mesh="front_axis" />
                <geom type="mesh" rgba="0.792157 0.819608 0.933333 1" mesh="front_axis" />
                <body name="FL_wheel" pos="-0.18 0.05 0" quat="0.268193 0.654272 0.654272 -0.268193">
                    <inertial pos="0 -0.015 0" quat="0.707107 0 0 0.707107" mass="0.190852" diaginertia="0.000193237 0.000110933 0.000110933" />
                    <joint name="FL_joint" pos="0 0 0" axis="0 1 0" />
                    <geom type="mesh" contype="0" conaffinity="0" group="1" rgba="0.792157 0.819608 0.933333 1" mesh="FL_wheel" />
                    <geom type="mesh" rgba="0.792157 0.819608 0.933333 1" mesh="FL_wheel" />
                </body>
                <body name="FR_wheel" pos="0.18 0.05 0" quat="0.451705 0.544024 -0.544024 0.451705">
                    <inertial pos="0 -0.015 0" quat="0.707107 0 0 0.707107" mass="0.190852" diaginertia="0.000193237 0.000110933 0.000110933" />
                    <joint name="FR_joint" pos="0 0 0" axis="0 1 0" />
                    <geom type="mesh" contype="0" conaffinity="0" group="1" rgba="0.792157 0.819608 0.933333 1" mesh="FR_wheel" />
                    <geom type="mesh" rgba="0.792157 0.819608 0.933333 1" mesh="FR_wheel" />
                </body>
            </body>
            <body name="BL_wheel" pos="0.2 -0.05 0.18" quat="0 0 0.707107 0.707107">
                <inertial pos="0 0.015 0" quat="0.707107 0 0 0.707107" mass="0.190852" diaginertia="0.000193237 0.000110933 0.000110933" />
                <joint name="BL_joint" pos="0 0 0" axis="0 1 0" />
                <geom type="mesh" contype="0" conaffinity="0" group="1" rgba="0.792157 0.819608 0.933333 1" mesh="BL_wheel" />
                <geom type="mesh" rgba="0.792157 0.819608 0.933333 1" mesh="BL_wheel" />
            </body>
            <body name="BR_wheel" pos="0.2 -0.05 -0.18" quat="0 0 0.707107 0.707107">
                <inertial pos="0 -0.015 0" quat="0.707107 0 0 0.707107" mass="0.190852" diaginertia="0.000193237 0.000110933 0.000110933" />
                <joint name="BR_joint" pos="0 0 0" axis="0 1 0" />
                <geom type="mesh" contype="0" conaffinity="0" group="1" rgba="0.792157 0.819608 0.933333 1" mesh="BR_wheel" />
                <geom type="mesh" rgba="0.792157 0.819608 0.933333 1" mesh="BR_wheel" />
            </body>
        </body>
    </worldbody>
</mujoco>
