<mujoco model="Drone_ver1_urdf">
    <compiler angle="radian" meshdir="meshes/" />
    <size njmax="500" nconmax="100" />
    <asset>
        <mesh name="reference_plate" file="reference_plate.STL" />
        <mesh name="main_body" file="main_body.STL" />
        <mesh name="FL_blade" file="FL_blade.STL" />
        <mesh name="BL_blade" file="BL_blade.STL" />
        <mesh name="FR_blade" file="FR_blade.STL" />
        <mesh name="BR_blade" file="BR_blade.STL" />
    </asset>
    <worldbody>
        <geom type="mesh" contype="0" conaffinity="0" group="1" rgba="0.792157 0.819608 0.933333 1" mesh="reference_plate" />
        <geom type="mesh" rgba="0.792157 0.819608 0.933333 1" mesh="reference_plate" />
        <body name="main_body" pos="0 0 0" quat="0.653281 -0.653281 -0.270598 0.270598">
            <inertial pos="1.51341e-05 -0.0114215 -1.51759e-05" quat="0.653416 0.270518 0.27062 0.653171" mass="0.153935" diaginertia="0.00022914 0.000122973 0.000121538" />
            <joint name="ref_to_mainbody" pos="0 0 0" axis="0 1 0" />
            <geom type="mesh" contype="0" conaffinity="0" group="1" rgba="0.792157 0.819608 0.933333 1" mesh="main_body" />
            <geom type="mesh" rgba="0.792157 0.819608 0.933333 1" mesh="main_body" />
            <body name="FL_blade" pos="0.123715 -0.018 0" quat="0 -0.950714 0 -0.310071">
                <inertial pos="0 0.0025 0" quat="0.5 0.5 0.5 0.5" mass="0.00736933" diaginertia="9.62503e-06 4.82787e-06 4.82787e-06" />
                <joint name="FL_joint" pos="0 0 0" axis="0 1 0" />
                <geom type="mesh" contype="0" conaffinity="0" group="1" rgba="0.792157 0.819608 0.933333 1" mesh="FL_blade" />
                <geom type="mesh" rgba="0.792157 0.819608 0.933333 1" mesh="FL_blade" />
            </body>
            <body name="BL_blade" pos="0 -0.018 0.123715" quat="0.630389 0 -0.77628 0">
                <inertial pos="0 -0.0025 0" quat="0.707107 0 0 0.707107" mass="0.00736933" diaginertia="9.62503e-06 4.82787e-06 4.82787e-06" />
                <joint name="BL_joint" pos="0 0 0" axis="0 1 0" />
                <geom type="mesh" contype="0" conaffinity="0" group="1" rgba="0.792157 0.819608 0.933333 1" mesh="BL_blade" />
                <geom type="mesh" rgba="0.792157 0.819608 0.933333 1" mesh="BL_blade" />
            </body>
            <body name="FR_blade" pos="0 -0.018 -0.123715" quat="0 -0.951214 0 0.308532">
                <inertial pos="0 0.0025 0" quat="0.707107 0 0 0.707107" mass="0.00736933" diaginertia="9.62503e-06 4.82787e-06 4.82787e-06" />
                <joint name="FR_joint" pos="0 0 0" axis="0 1 0" />
                <geom type="mesh" contype="0" conaffinity="0" group="1" rgba="0.792157 0.819608 0.933333 1" mesh="FR_blade" />
                <geom type="mesh" rgba="0.792157 0.819608 0.933333 1" mesh="FR_blade" />
            </body>
            <body name="BR_blade" pos="-0.123715 -0.018 0" quat="0.28506 0 -0.95851 0">
                <inertial pos="0 -0.0025 0" quat="0.707107 0 0 0.707107" mass="0.00736933" diaginertia="9.62503e-06 4.82787e-06 4.82787e-06" />
                <joint name="BR_joint" pos="0 0 0" axis="0 1 0" />
                <geom type="mesh" contype="0" conaffinity="0" group="1" rgba="0.792157 0.819608 0.933333 1" mesh="BR_blade" />
                <geom type="mesh" rgba="0.792157 0.819608 0.933333 1" mesh="BR_blade" />
            </body>
        </body>
    </worldbody>
</mujoco>
